Workbook

Sheet PQRs
A1: CASO | B1: TRAMITE | C1: TIMESTAP | D1: CONTACTO | E1: ESTADO | F1: PRIORIDAD | G1: ASESOR ASIGNADO | H1: FECHA DE ASIGNACION | I1: Column 9 | J1: Column 10 | K1: Column 11 | L1: Column 12
A2: 1 | B2: QUEJA | C2: 2026-02-17T10:08:27.4016176 | D2: {"solicitante":{"nombreCompleto":"María González López","tipoDocumento":"CE","numeroDocumento":"9876543210","email":"maria.gonzalez@example.com","telefono":"3109876543"},"tramite":{"tipoSolicitud":"QUEJA","productoRelacionado":"ATENCION_CLIENTE","asunto":"Recibí mala atención en la oficina principal el día de ayer","descripcionDetallada":"Recibí mala atención en la oficina principal el día de ayer","fechaCreacion":"2026-02-17T10:08:27.4016176"}} | E2: Pendiente | F2: Baja | G2: yo@proyectiva.com | H2: 46064 | I2: 46064 | J2: [{"fecha":"2026-02-19T23:28:10.058Z","usuario":"cristian.mosquera@segurosbolivar.com","accion":"esto es un ejemplo","estadoAnterior":"Pendiente","estadoNuevo":"Pendiente"}]
A3: PQR-20260220-0013 | B3: PETICION | C3: 2026-02-20T08:25:46.503748318 | D3: {"solicitante":{"nombreCompleto":"Nicolas 2","tipoDocumento":"CC","numeroDocumento":"1000969735","email":"nicolas.cano@serviciosbolivar.com","telefono":"3193403518"},"tramite":{"tipoSolicitud":"PETICION","productoRelacionado":"SALUD","asunto":"prueba asunto","descripcionDetallada":"pruebaaaaaaaaaaaaaaaaaaaaaaaaaaaaaaaaaaaaaa","fechaCreacion":"2026-02-20T08:25:46.503748318"}} | E3: En Proceso | F3: Media | G3: maria.gaitan@proyectivaseguros.com | H3: 2026-02-24T14:31:55.370Z | J3: [{"fecha":"2026-02-24T14:31:55.330Z","usuario":"cristian.mosquera@segurosbolivar.com","accion":"PQR asignada a maria.gaitan@proyectivaseguros.com desde panel administrativo.","estadoAnterior":"Pendiente","estadoNuevo":"En Proceso"}]
A4: PQR-20260220-0011 | B4: QUEJA | C4: 2026-02-20T07:16:17.372854713 | D4: {"solicitante":{"nombreCompleto":"María González López","tipoDocumento":"CE","numeroDocumento":"98765432210","email":"maria.gonzalez@example.com","telefono":"3109876543"},"tramite":{"tipoSolicitud":"QUEJA","productoRelacionado":"SALUD","asunto":"test asunto","descripcionDetallada":"Recibí mala atención en la oficina principal el día de ayer","fechaCreacion":"2026-02-20T07:16:17.372854713"}} | E4: En Proceso | F4: Media | G4: maria.gaitan@proyectivaseguros.com | H4: 2026-02-24T14:31:55.328Z | J4: [{"fecha":"2026-02-24T14:31:55.295Z","usuario":"cristian.mosquera@segurosbolivar.com","accion":"PQR asignada a maria.gaitan@proyectivaseguros.com desde panel administrativo.","estadoAnterior":"Pendiente","estadoNuevo":"En Proceso"}]
A5: PQR-20260220-0012 | B5: FELICITACIONES | C5: 2026-02-20T08:14:54.700900395 | D5: {"solicitante":{"nombreCompleto":"Julio Alfredo Roncallo Polo","tipoDocumento":"CC","numeroDocumento":"1082962828","email":"julio.roncallo@segurosbolivar.com","telefono":"3229720435"},"tramite":{"tipoSolicitud":"FELICITACIONES","productoRelacionado":"OTRO","asunto":"Felicitaciones","descripcionDetallada":"Equipo de desarrollo proyectiva, felicitaciones por este arduo trabajo en equipo, se entrelazan desde el amor y el codigo el equipo del back con el front","fechaCreacion":"2026-02-20T08:14:54.700900395"}}
A6: PQR-20260220-0014 | B6: PETICION | C6: 2026-02-20T15:43:47.023715303 | D6: {"solicitante":{"nombreCompleto":"Nicolas Cano","tipoDocumento":"CC","numeroDocumento":"1000969735","email":"nicolas.cano@serviciosbolivar.com","telefono":"3193403518"},"tramite":{"tipoSolicitud":"PETICION","productoRelacionado":"OTRO","asunto":"prueba asunto","descripcionDetallada":"pruebaaaaaaaaaaaaaaaaaaaa","fechaCreacion":"2026-02-20T15:43:47.023715303"}}
A7: PQR-20260220-0015 | B7: PETICION | C7: 2026-02-20T15:51:52.725596096 | D7: {"solicitante":{"nombreCompleto":"Rodrigo Suarez","tipoDocumento":"NIT","numeroDocumento":"1192765243","email":"rodrigo@gmail.com","telefono":"3216363324"},"tramite":{"tipoSolicitud":"PETICION","productoRelacionado":"OTRO","asunto":"No me sirve la página","descripcionDetallada":"Quién hizo estpoooo ","fechaCreacion":"2026-02-20T15:51:52.725596096"}}
A8: PQR-20260220-0016 | B8: SUGERENCIA | C8: 2026-02-20T15:54:28.232192577 | D8: {"solicitante":{"nombreCompleto":"Nicolas Cano 5","tipoDocumento":"CC","numeroDocumento":"1000969735","email":"nicolas.cano@serviciosbolivar.com","telefono":"3193403518"},"tramite":{"tipoSolicitud":"SUGERENCIA","productoRelacionado":"OTRO","asunto":"prueba asunto","descripcionDetallada":"prueba 2222222222222222222222","fechaCreacion":"2026-02-20T15:54:28.232192577"}} | E8: Pendiente | F8: Media | G8: cristian.mosquera@segurosbolivar.com | H8: 2026-02-24T21:25:49.806Z | J8: [{"fecha":"2026-02-24T21:25:49.778Z","usuario":"cristian.mosquera@segurosbolivar.com","accion":"Asignación desde panel admin","estadoAnterior":"Pendiente","estadoNuevo":"Pendiente"}]
A9: PQR-20260223-0017 | B9: PETICION | C9: 46076.343 | D9: {"solicitante":{"nombreCompleto":"María Fernanda López Martínez","tipoDocumento":"CC","numeroDocumento":"5298765432","email":"maria.lopez@example.com","telefono":"3109876543"},"tramite":{"tipoSolicitud":"PETICION","productoRelacionado":"SALUD","asunto":"Consulta sobre cobertura de robo","descripcionDetallada":"Deseo conocer los detalles de la cobertura de robo incluida en mi póliza de hogar.","fechaCreacion":"2026-02-23 8:13:15"}} | E9: Pendiente | F9: Media | G9: desarrollocrmlibertador@ellibertador.co | H9: 2026-02-24T21:25:32.919Z | J9: [{"fecha":"2026-02-24T21:25:32.719Z","usuario":"cristian.mosquera@segurosbolivar.com","accion":"Asignación desde panel admin","estadoAnterior":"Pendiente","estadoNuevo":"Pendiente"}]
A10: PQR-20260224-0001 | B10: QUEJA | C10: 46077.715 | D10: {"solicitante":{"nombreCompleto":"María González López Diaz","tipoDocumento":"CE","numeroDocumento":"1192722255","email":"maria.gonzalez@example.com","telefono":"3109876543"},"tramite":{"tipoSolicitud":"QUEJA","productoRelacionado":"SALUD","asunto":"test asunto","descripcionDetallada":"Recibí mala atención en la oficina principal el día de ayer","fechaCreacion":"2026-02-24 17:09:45"}}
A11: PQR-20260224-0002 | B11: FELICITACIONES | C11: 46077.716 | D11: {"solicitante":{"nombreCompleto":"María González López Diaz","tipoDocumento":"CE","numeroDocumento":"1192722255","email":"maria.gonzalez@example.com","telefono":"3109876543"},"tramite":{"tipoSolicitud":"FELICITACIONES","productoRelacionado":"SALUD","asunto":"test asunto","descripcionDetallada":"Recibí mala atención en la oficina principal el día de ayer","fechaCreacion":"2026-02-24 17:11:23"}}
A12: PQR-20260225-0018 | B12: FELICITACIONES | C12: 46078.347 | D12: {"solicitante":{"nombreCompleto":"Julio Alfredo Roncallo Polo","tipoDocumento":"CC","numeroDocumento":"1082962828","email":"julio.roncallo@segurosbolivar.com","telefono":"3229720435"},"tramite":{"tipoSolicitud":"FELICITACIONES","productoRelacionado":"OTRO","asunto":"Felicitaciones","descripcionDetallada":"este es un mensaje de prueba","fechaCreacion":"2026-02-25 8:20:22"}}
A13: PQR-20260225-0019 | B13: PETICION | C13: 46078.406 | D13: {"solicitante":{"nombreCompleto":"Nicolas Cano pqrsf","tipoDocumento":"CC","numeroDocumento":"1000969735","email":"nicolas.cano@serviciosbolivar.com","telefono":"3193403518"},"tramite":{"tipoSolicitud":"PETICION","productoRelacionado":"OTRO","asunto":"prueba asunto","descripcionDetallada":"pruebaaaaaaaaaaaaaaaaaaa","fechaCreacion":"2026-02-25 9:45:01"}}
A14: PQR-20260225-0020 | B14: PETICION | C14: 46078.607 | D14: {"solicitante":{"nombreCompleto":"Nicolas Cano","tipoDocumento":"CC","numeroDocumento":"1000969735","email":"nicolas.cano@segurosbolivar.com","telefono":"3193403518"},"tramite":{"tipoSolicitud":"PETICION","productoRelacionado":"EMPRESA","asunto":"prueba asunto","descripcionDetallada":"pruebaaaaaaaaaaaaaaaaaaaaaa","fechaCreacion":"2026-02-25 14:34:27"}}

Sheet Leads
A1: Fecha ingreso | B1: Numero Solicitud | C1: Datos del lead | D1: Nombre agente | E1: Etapa Funel | F1: Estado Gestion | G1: Producto | H1: Observaciones | I1: fecha ultima gestion | J1: datos vida | K1: datos desempleo
A2: 45881.375 | B2: 7847382 | C2: {"poliza":"2252","nombre":"FABIAN ANDRES PERILLA MANJARES","id":"1019098199","telefono":"","correo":"","ciudad":"BOGOTA, D.C.","direccion":"CR 57 128B BIS 06","tipoInmueble":"Vivienda","canon":"1300000","fechaRadicacion":"11/08/2025 3:08:43","fechaAprobacion":"11/08/2025 4:08:58","estado":"APROBADA"} | D2: Anyuley.daza@aselibertador.com | E2: Contacto Inicial y Datos | F2: DESISTIDO | G2: Seguro de Vida | H2: [{"fecha":"2025-08-12 09:21:32","usuario":"anyuley.daza@aselibertador.com","accionRealizada":"DESISTIDO","leadEtapaActual":"Contacto Inicial y Datos","productosGestion":"Seguro de Vida","observaciones":"No Contesta"}] | I2: 45881.39 | J2: {"Contacto Inicial y Datos":{"nomAgt":"","emailCte":"","autorizaDatosPersonales":false,"fechaNacimiento":"","tipoDocumento":"","observacionesPresentacion":"No hay número de contacto se valida sai y tampoco hay registro","genero":"","resultadoGestion":"Cliente ilocalizable","accion":"Cliente ilocalizable","usuario":"anyuley.daza@aselibertador.com"},"Cotización y Pre-Asegurabilidad":{"periosidad":"","nPagosMensuales":"","admin":"","observacionesCotizacion":"","valorAseguradoVida":0,"primaVidaITP":0,"fechaCotizacionVida":""},"Declaración de Asegurabilidad":{"actividadesLicita":false,"procesoPenal":false,"frecuenciaDeportesAltoRiesgo":"","peso":"","estatura":"","imcCalculado":"","observacionImc":"","estadoAsegurabilidad":"","hipertensionArterial":false,"colesterolTrigliceridosElevados":false,"diabetes":false,"enfermedadCoronariaInfarto":false,"insuficienciaRenal":false,"cancerTumores":false,"derrameTrombosisCerebral":false,"enfermedadesPsicologicasPsiquiatricas":false,"sidaVih":false,"pruebaVihPositiva":false,"secuelasEnfermedadAccidente":"","diagnosticoEnfermedadFracturas":"","tratamientoAlcoholAlucinogenos":false,"cirugiaProgramada":false,"autorizacionInformacionMedica":false,"fechaAsegurabilidad":""},"Autorización de Descuento Débito":{"canalDescuento":"","tipoDeCuenta":"","entidadBancaria":"","numeroCuentaDebito":"","fechaVencimientoTC":"","numeroCuotasTC":"","autorizaDescuentoAutomatico":false,"entiendeMoraPrima":false,"valorPrima":0,"fechaAutorizacionDebito":"","observacionesCierre":""},"Beneficiarios y Autorizaciones":{"nombreBeneficiario1":"","apellidoBeneficiario1":"","parentescoBeneficiario1":"","designacionBeneficiario1":0,"nombreBeneficiario2":"","apellidoBeneficiario2":"","parentescoBeneficiario2":"","designacionBeneficiario2":0,"nombreBeneficiario3":"","apellidoBeneficiario3":"","parentescoBeneficiario3":"","designacionBeneficiario3":0,"beneficiariosRegistrados":false,"fechaRegistroBeneficiarios":""},"Emisión de Póliza":{"numeroCertificadoFinal":"","resultadoEmision":"","fechaVigenciaPoliza":"","polizaPrincipal":"","periodicidadPagoPoliza":"MENSUAL","confirmacionVentaSegurosBolivar":false,"liderClavo":"","certificado":"75272","observacionesEmision":"","fechaEmisionPoliza":"","estadoPoliza":"","numeroContrato":""}}
A3: 45881.375 | B3: 7847475 | C3: {"poliza":"1136","nombre":"GROUP SAS MARQUESA GROUP","id":"901769660","telefono":"3123027512","correo":"gerencia@marquesagroup.co","ciudad":"BOGOTA, D.C.","direccion":"CL 56 4 A 11","tipoInmueble":"Comercial","canon":"13090000","fechaRadicacion":"11/08/2025 9:08:31","fechaAprobacion":"11/08/2025 1:08:58","estado":"APROBADA"} | D3: maria.gaitan@proyectivaseguros.com | E3: Contacto Inicial y Datos | F3: DESISTIDO | G3: Seguro de Vida | H3: [{"fecha":"2025-08-12 09:29:47","usuario":"maria.gaitan@segurosbolivar.com","accionRealizada":"DESISTIDO","leadEtapaActual":"Contacto Inicial y Datos","productosGestion":"Seguro de Vida","observaciones":"Preguntas Sarlaft cliente sin CC"}] | I3: 45881.396 | J3: {"Contacto Inicial y Datos":{"nomAgt":"","emailCte":"","autorizaDatosPersonales":false,"fechaNacimiento":"","tipoDocumento":"","observacionesPresentacion":"","genero":"","resultadoGestion":"","accion":"No Asegurable","usuario":"maria.gaitan@segurosbolivar.com"},"Cotización y Pre-Asegurabilidad":{"periosidad":"","nPagosMensuales":"","admin":"","observacionesCotizacion":"","valorAseguradoVida":0,"primaVidaITP":0,"fechaCotizacionVida":""},"Declaración de Asegurabilidad":{"actividadesLicita":false,"procesoPenal":false,"frecuenciaDeportesAltoRiesgo":"","peso":"","estatura":"","imcCalculado":"","observacionImc":"","estadoAsegurabilidad":"","hipertensionArterial":false,"colesterolTrigliceridosElevados":false,"diabetes":false,"enfermedadCoronariaInfarto":false,"insuficienciaRenal":false,"cancerTumores":false,"derrameTrombosisCerebral":false,"enfermedadesPsicologicasPsiquiatricas":false,"sidaVih":false,"pruebaVihPositiva":false,"secuelasEnfermedadAccidente":"","diagnosticoEnfermedadFracturas":"","tratamientoAlcoholAlucinogenos":false,"cirugiaProgramada":false,"autorizacionInformacionMedica":false,"fechaAsegurabilidad":""},"Autorización de Descuento Débito":{"canalDescuento":"","tipoDeCuenta":"","entidadBancaria":"","numeroCuentaDebito":"","fechaVencimientoTC":"","numeroCuotasTC":"","autorizaDescuentoAutomatico":false,"entiendeMoraPrima":false,"valorPrima":0,"fechaAutorizacionDebito":"","observacionesCierre":""},"Beneficiarios y Autorizaciones":{"nombreBeneficiario1":"","apellidoBeneficiario1":"","parentescoBeneficiario1":"","designacionBeneficiario1":0,"nombreBeneficiario2":"","apellidoBeneficiario2":"","parentescoBeneficiario2":"","designacionBeneficiario2":0,"nombreBeneficiario3":"","apellidoBeneficiario3":"","parentescoBeneficiario3":"","designacionBeneficiario3":0,"beneficiariosRegistrados":false,"fechaRegistroBeneficiarios":""},"Emisión de Póliza":{"numeroCertificadoFinal":"","resultadoEmision":"","fechaVigenciaPoliza":"","polizaPrincipal":"","periodicidadPagoPoliza":"MENSUAL","confirmacionVentaSegurosBolivar":false,"liderClavo":"","certificado":"75272","observacionesEmision":"","fechaEmisionPoliza":"","estadoPoliza":"","numeroContrato":""}}
A4: 45881.375 | B4: 11696200 | C4: {"poliza":"429","nombre":"BLANCA ALICIA OROZCO PATINO","id":"51559718","telefono":"3229442151","correo":"blancorozko@yahoo.es","ciudad":"BOGOTA, D.C.","direccion":"CL 60A SUR 73 40 TO 2 AP 308","tipoInmueble":"Vivienda","canon":"1100000","fechaRadicacion":"11/08/2025 2:08:07","fechaAprobacion":"11/08/2025 10:08:28","estado":"APROBADA"} | D4: angela.caipa@segurosbolivar.com | E4: Contacto Inicial y Datos | F4: DESISTIDO | G4: Seguro de Vida | H4: [{"fecha":"2025-08-12 09:29:17","usuario":"anyuley.daza@aselibertador.com","accionRealizada":"DESISTIDO","leadEtapaActual":"Contacto Inicial y Datos","productosGestion":"Seguro de Vida","observaciones":"No Contesta"}] | I4: 45881.395 | J4: {"Contacto Inicial y Datos":{"nomAgt":"","emailCte":"","autorizaDatosPersonales":false,"fechaNacimiento":"","tipoDocumento":"","observacionesPresentacion":"","genero":"","resultadoGestion":"Cliente ilocalizable","accion":"Cliente ilocalizable","usuario":"anyuley.daza@aselibertador.com"},"Cotización y Pre-Asegurabilidad":{"periosidad":"","nPagosMensuales":"","admin":"","observacionesCotizacion":"","valorAseguradoVida":0,"primaVidaITP":0,"fechaCotizacionVida":""},"Declaración de Asegurabilidad":{"actividadesLicita":false,"procesoPenal":false,"frecuenciaDeportesAltoRiesgo":"","peso":"","estatura":"","imcCalculado":"","observacionImc":"","estadoAsegurabilidad":"","hipertensionArterial":false,"colesterolTrigliceridosElevados":false,"diabetes":false,"enfermedadCoronariaInfarto":false,"insuficienciaRenal":false,"cancerTumores":false,"derrameTrombosisCerebral":false,"enfermedadesPsicologicasPsiquiatricas":false,"sidaVih":false,"pruebaVihPositiva":false,"secuelasEnfermedadAccidente":"","diagnosticoEnfermedadFracturas":"","tratamientoAlcoholAlucinogenos":false,"cirugiaProgramada":false,"autorizacionInformacionMedica":false,"fechaAsegurabilidad":""},"Autorización de Descuento Débito":{"canalDescuento":"","tipoDeCuenta":"","entidadBancaria":"","numeroCuentaDebito":"","fechaVencimientoTC":"","numeroCuotasTC":"","autorizaDescuentoAutomatico":false,"entiendeMoraPrima":false,"valorPrima":0,"fechaAutorizacionDebito":"","observacionesCierre":""},"Beneficiarios y Autorizaciones":{"nombreBeneficiario1":"","apellidoBeneficiario1":"","parentescoBeneficiario1":"","designacionBeneficiario1":0,"nombreBeneficiario2":"","apellidoBeneficiario2":"","parentescoBeneficiario2":"","designacionBeneficiario2":0,"nombreBeneficiario3":"","apellidoBeneficiario3":"","parentescoBeneficiario3":"","designacionBeneficiario3":0,"beneficiariosRegistrados":false,"fechaRegistroBeneficiarios":""},"Emisión de Póliza":{"numeroCertificadoFinal":"","resultadoEmision":"","fechaVigenciaPoliza":"","polizaPrincipal":"","periodicidadPagoPoliza":"MENSUAL","confirmacionVentaSegurosBolivar":false,"liderClavo":"","certificado":"75272","observacionesEmision":"","fechaEmisionPoliza":"","estadoPoliza":"","numeroContrato":""}}
A5: 45881.375 | B5: 11696324 | C5: {"poliza":"139","nombre":"DOLLY MARIA OROZCO GALLEGO","id":"51653652","telefono":"3163506755","correo":"dollymaorozco@gmail.com","ciudad":"BOGOTA, D.C.","direccion":"CL 163 B 50 64 IN 5 AP 21","tipoInmueble":"Vivienda","canon":"1800000","fechaRadicacion":"11/08/2025 9:08:58","fechaAprobacion":"11/08/2025 2:08:20","estado":"APROBADA"} | D5: maria.gaitan@proyectivaseguros.com | E5: Contacto Inicial y Datos | F5: DESISTIDO | G5: Seguro de Vida | H5: [{"fecha":"2025-08-12 09:31:36","usuario":"maria.gaitan@segurosbolivar.com","accionRealizada":"DESISTIDO","leadEtapaActual":"Contacto Inicial y Datos","productosGestion":"Seguro de Vida","observaciones":"Edad no asegurable"},{"fecha":"2025-08-15 11:59:54","usuario":"anyuley.daza@aselibertador.com","accionRealizada":"DESISTIDO","leadEtapaActual":"Contacto Inicial y Datos","productosGestion":"Seguro de Vida","observaciones":"No Contesta"},{"fecha":"2025-08-15 12:00:51","usuario":"anyuley.daza@aselibertador.com","accionRealizada":"DESISTIDO","leadEtapaActual":"Contacto Inicial y Datos","productosGestion":"Seguro de Vida","observaciones":"No Contesta"},{"fecha":"2025-08-15 12:03:50","usuario":"anyuley.daza@aselibertador.com","accionRealizada":"DESISTIDO","leadEtapaActual":"Contacto Inicial y Datos","productosGestion":"Seguro de Vida","observaciones":"No Contesta"},{"fecha":"2025-08-15 12:21:15","usuario":"anyuley.daza@aselibertador.com","accionRealizada":"DESISTIDO","leadEtapaActual":"Contacto Inicial y Datos","productosGestion":"Seguro de Vida","observaciones":"No Contesta"},{"fecha":"2025-08-15 12:49:14","usuario":"anyuley.daza@aselibertador.com","accionRealizada":"DESISTIDO","leadEtapaActual":"Contacto Inicial y Datos","productosGestion":"Seguro de Vida","observaciones":"No Contesta"},{"fecha":"2025-08-16 10:04:30","usuario":"anyuley.daza@aselibertador.com","accionRealizada":"DESISTIDO","leadEtapaActual":"Contacto Inicial y Datos","productosGestion":"Seguro de Vida","observaciones":"No Contesta"},{"fecha":"2025-08-19 12:36:15","usuario":"anyuley.daza@aselibertador.com","accionRealizada":"DESISTIDO","leadEtapaActual":"Contacto Inicial y Datos","productosGestion":"Seguro de Vida","observaciones":"No Contesta"},{"fecha":"2025-08-19 12:37:17","usuario":"anyuley.daza@aselibertador.com","accionRealizada":"DESISTIDO","leadEtapaActual":"Contacto Inicial y Datos","productosGestion":"Seguro de Vida","observaciones":"No Contesta"}] | I5: 45888.526 | J5: {"Contacto Inicial y Datos":{"nomAgt":"","emailCte":"","autorizaDatosPersonales":false,"fechaNacimiento":"","tipoDocumento":"","observacionesPresentacion":"Se marca tres vces,No contesta","genero":"","resultadoGestion":"Cliente ilocalizable","accion":"Cliente ilocalizable","usuario":"anyuley.daza@aselibertador.com"},"Cotización y Pre-Asegurabilidad":{"periosidad":"","nPagosMensuales":"","admin":"","observacionesCotizacion":"","valorAseguradoVida":0,"primaVidaITP":0,"fechaCotizacionVida":""},"Declaración de Asegurabilidad":{"actividadesLicita":false,"procesoPenal":false,"frecuenciaDeportesAltoRiesgo":"","peso":"","estatura":"","imcCalculado":"","observacionImc":"","estadoAsegurabilidad":"","hipertensionArterial":false,"colesterolTrigliceridosElevados":false,"diabetes":false,"enfermedadCoronariaInfarto":false,"insuficienciaRenal":false,"cancerTumores":false,"derrameTrombosisCerebral":false,"enfermedadesPsicologicasPsiquiatricas":false,"sidaVih":false,"pruebaVihPositiva":false,"secuelasEnfermedadAccidente":"","diagnosticoEnfermedadFracturas":"","tratamientoAlcoholAlucinogenos":false,"cirugiaProgramada":false,"autorizacionInformacionMedica":false,"fechaAsegurabilidad":""},"Autorización de Descuento Débito":{"canalDescuento":"","tipoDeCuenta":"","entidadBancaria":"","numeroCuentaDebito":"","fechaVencimientoTC":"","numeroCuotasTC":"","autorizaDescuentoAutomatico":false,"entiendeMoraPrima":false,"valorPrima":0,"fechaAutorizacionDebito":"","observacionesCierre":""},"Beneficiarios y Autorizaciones":{"nombreBeneficiario1":"","apellidoBeneficiario1":"","parentescoBeneficiario1":"","designacionBeneficiario1":0,"nombreBeneficiario2":"","apellidoBeneficiario2":"","parentescoBeneficiario2":"","designacionBeneficiario2":0,"nombreBeneficiario3":"","apellidoBeneficiario3":"","parentescoBeneficiario3":"","designacionBeneficiario3":0,"beneficiariosRegistrados":false,"fechaRegistroBeneficiarios":""},"Emisión de Póliza":{"numeroCertificadoFinal":"","resultadoEmision":"","fechaVigenciaPoliza":"","polizaPrincipal":"","periodicidadPagoPoliza":"MENSUAL","confirmacionVentaSegurosBolivar":false,"liderClavo":"","certificado":"75272","observacionesEmision":"","fechaEmisionPoliza":"","estadoPoliza":"","numeroContrato":""}}
A6: 45881.787 | B6: 7847403 | C6: {"poliza":"11474","nombre":"YEIFIN ANDRES BAYONA GUERREO","id":"1193131955","telefono":"3228601520","correo":"YELFINBAYONA@ICLOUD.COM","ciudad":"BUCARAMANGA","direccion":"DG 9 7B 93","tipoInmueble":"Vivienda","canon":"900000","fechaRadicacion":"12/8/2025","fechaAprobacion":"12/8/2025","estado":"APROBADA"} | D6: ana.prieto@aselibertador.com | E6: Contacto Inicial y Datos | F6: DESISTIDO | G6: Seguro de Vida | H6: [{"fecha":"2025-08-13 09:14:17","usuario":"ana.prieto@aselibertador.com","accionRealizada":"DESISTIDO","leadEtapaActual":"Contacto Inicial y Datos","productosGestion":"Seguro de Vida","observaciones":"No Contesta"}] | I6: 45882.385 | J6: {"Contacto Inicial y Datos":{"nomAgt":"","emailCte":"","autorizaDatosPersonales":false,"fechaNacimiento":"","tipoDocumento":"CC","observacionesPresentacion":"","genero":"Masculino","resultadoGestion":"Cliente ilocalizable","accion":"Cliente ilocalizable","usuario":"ana.prieto@aselibertador.com"},"Cotización y Pre-Asegurabilidad":{"periosidad":"","nPagosMensuales":"","admin":"","observacionesCotizacion":"","valorAseguradoVida":0,"primaVidaITP":0,"fechaCotizacionVida":""},"Declaración de Asegurabilidad":{"actividadesLicita":false,"procesoPenal":false,"frecuenciaDeportesAltoRiesgo":"","peso":"","estatura":"","imcCalculado":"","observacionImc":"","estadoAsegurabilidad":"","hipertensionArterial":false,"colesterolTrigliceridosElevados":false,"diabetes":false,"enfermedadCoronariaInfarto":false,"insuficienciaRenal":false,"cancerTumores":false,"derrameTrombosisCerebral":false,"enfermedadesPsicologicasPsiquiatricas":false,"sidaVih":false,"pruebaVihPositiva":false,"secuelasEnfermedadAccidente":"","diagnosticoEnfermedadFracturas":"","tratamientoAlcoholAlucinogenos":false,"cirugiaProgramada":false,"autorizacionInformacionMedica":false,"fechaAsegurabilidad":""},"Autorización de Descuento Débito":{"canalDescuento":"","tipoDeCuenta":"","entidadBancaria":"","numeroCuentaDebito":"","fechaVencimientoTC":"","numeroCuotasTC":"","autorizaDescuentoAutomatico":false,"entiendeMoraPrima":false,"valorPrima":0,"fechaAutorizacionDebito":"","observacionesCierre":""},"Beneficiarios y Autorizaciones":{"nombreBeneficiario1":"","apellidoBeneficiario1":"","parentescoBeneficiario1":"","designacionBeneficiario1":0,"nombreBeneficiario2":"","apellidoBeneficiario2":"","parentescoBeneficiario2":"","designacionBeneficiario2":0,"nombreBeneficiario3":"","apellidoBeneficiario3":"","parentescoBeneficiario3":"","designacionBeneficiario3":0,"beneficiariosRegistrados":false,"fechaRegistroBeneficiarios":""},"Emisión de Póliza":{"numeroCertificadoFinal":"","resultadoEmision":"","fechaVigenciaPoliza":"","polizaPrincipal":"","periodicidadPagoPoliza":"MENSUAL","confirmacionVentaSegurosBolivar":false,"liderClavo":"","certificado":"75272","observacionesEmision":"","fechaEmisionPoliza":"","estadoPoliza":"","numeroContrato":""}}
A7: 45881.787 | B7: 7847488 | C7: {"poliza":"11196","nombre":"MIGUEL ANTONIO JAIMES FLOREZ","id":"13249605","telefono":"3203459151","correo":"MAJAFLO@HOTMAIL.COM","ciudad":"BUCARAMANGA","direccion":"ALTOS DE LA CANAVERA TERCERA T 5 AP 403","tipoInmueble":"Vivienda","canon":"850000","fechaRadicacion":"11/8/2025","fechaAprobacion":"12/8/2025","estado":"APROBADA"} | D7: cristian.mosquera@segurosbolivar.com | E7: Contacto Inicial y Datos | G7: Seguro de Vida | H7: [{"fecha":"2025-08-14 16:17:35","usuario":"diana.salas@segurosbolivar.com","accionRealizada":"DESISTIDO","leadEtapaActual":"Contacto Inicial y Datos","productosGestion":"Seguro de Vida","observaciones":"Edad no asegurable"}] | I7: 45883.679 | J7: {"Contacto Inicial y Datos":{"nomAgt":"","emailCte":"","autorizaDatosPersonales":false,"fechaNacimiento":"","tipoDocumento":"","observacionesPresentacion":"","genero":"","resultadoGestion":"","accion":"No Asegurable","usuario":"diana.salas@segurosbolivar.com"},"Cotización y Pre-Asegurabilidad":{"periosidad":"","nPagosMensuales":"","admin":"","observacionesCotizacion":"","valorAseguradoVida":0,"primaVidaITP":0,"fechaCotizacionVida":""},"Declaración de Asegurabilidad":{"actividadesLicita":false,"procesoPenal":false,"frecuenciaDeportesAltoRiesgo":"","peso":"","estatura":"","imcCalculado":"","observacionImc":"","estadoAsegurabilidad":"","hipertensionArterial":false,"colesterolTrigliceridosElevados":false,"diabetes":false,"enfermedadCoronariaInfarto":false,"insuficienciaRenal":false,"cancerTumores":false,"derrameTrombosisCerebral":false,"enfermedadesPsicologicasPsiquiatricas":false,"sidaVih":false,"pruebaVihPositiva":false,"secuelasEnfermedadAccidente":"","diagnosticoEnfermedadFracturas":"","tratamientoAlcoholAlucinogenos":false,"cirugiaProgramada":false,"autorizacionInformacionMedica":false,"fechaAsegurabilidad":""},"Autorización de Descuento Débito":{"canalDescuento":"","tipoDeCuenta":"","entidadBancaria":"","numeroCuentaDebito":"","fechaVencimientoTC":"","numeroCuotasTC":"","autorizaDescuentoAutomatico":false,"entiendeMoraPrima":false,"valorPrima":0,"fechaAutorizacionDebito":"","observacionesCierre":""},"Beneficiarios y Autorizaciones":{"nombreBeneficiario1":"","apellidoBeneficiario1":"","parentescoBeneficiario1":"","designacionBeneficiario1":0,"nombreBeneficiario2":"","apellidoBeneficiario2":"","parentescoBeneficiario2":"","designacionBeneficiario2":0,"nombreBeneficiario3":"","apellidoBeneficiario3":"","parentescoBeneficiario3":"","designacionBeneficiario3":0,"beneficiariosRegistrados":false,"fechaRegistroBeneficiarios":""},"Emisión de Póliza":{"numeroCertificadoFinal":"","resultadoEmision":"","fechaVigenciaPoliza":"","polizaPrincipal":"","periodicidadPagoPoliza":"MENSUAL","confirmacionVentaSegurosBolivar":false,"liderClavo":"","certificado":"75272","observacionesEmision":"","fechaEmisionPoliza":"","estadoPoliza":"","numeroContrato":""}}
A8: 45881.787 | B8: 7847493 | C8: {"poliza":"10670","nombre":"LUZ MERY HOYA CUESTA","id":"47441183","telefono":"3102824190","correo":"merynmoon7521@gmail.com","ciudad":"PALMIRA","direccion":"CR 44 3 26 80 AP 301B CLUB RESIDENCIAL OTOBO","tipoInmueble":"Vivienda","canon":"1800000","fechaRadicacion":"12/8/2025","fechaAprobacion":"12/8/2025","estado":"APROBADA"} | D8: maria.gaitan@proyectivaseguros.com | E8: Contacto Inicial y Datos | F8: DESISTIDO | G8: Seguro de Vida | H8: [{"fecha":"2025-08-13 08:13:45","usuario":"maria.gaitan@segurosbolivar.com","accionRealizada":"DESISTIDO","leadEtapaActual":"Contacto Inicial y Datos","productosGestion":"Seguro de Vida","observaciones":"No Contesta"}] | I8: 45882.343 | J8: {"Contacto Inicial y Datos":{"nomAgt":"","emailCte":"","autorizaDatosPersonales":false,"fechaNacimiento":"","tipoDocumento":"","observacionesPresentacion":"","genero":"","resultadoGestion":"Cliente ilocalizable","accion":"Cliente ilocalizable","usuario":"maria.gaitan@segurosbolivar.com"},"Cotización y Pre-Asegurabilidad":{"periosidad":"Mensual","nPagosMensuales":"12","admin":"","observacionesCotizacion":"","valorAseguradoVida":0,"primaVidaITP":0,"fechaCotizacionVida":"","resultadoGestion":""},"Declaración de Asegurabilidad":{"actividadesLicita":false,"procesoPenal":false,"frecuenciaDeportesAltoRiesgo":"","peso":"","estatura":"","imcCalculado":"","observacionImc":"","estadoAsegurabilidad":"","hipertensionArterial":false,"colesterolTrigliceridosElevados":false,"diabetes":false,"enfermedadCoronariaInfarto":false,"insuficienciaRenal":false,"cancerTumores":false,"derrameTrombosisCerebral":false,"enfermedadesPsicologicasPsiquiatricas":false,"sidaVih":false,"pruebaVihPositiva":false,"secuelasEnfermedadAccidente":"","diagnosticoEnfermedadFracturas":"","tratamientoAlcoholAlucinogenos":false,"cirugiaProgramada":false,"autorizacionInformacionMedica":false,"fechaAsegurabilidad":""},"Autorización de Descuento Débito":{"canalDescuento":"","tipoDeCuenta":"","entidadBancaria":"","numeroCuentaDebito":"","fechaVencimientoTC":"","numeroCuotasTC":"","autorizaDescuentoAutomatico":false,"entiendeMoraPrima":false,"valorPrima":0,"fechaAutorizacionDebito":"","observacionesCierre":""},"Beneficiarios y Autorizaciones":{"nombreBeneficiario1":"","apellidoBeneficiario1":"","parentescoBeneficiario1":"","designacionBeneficiario1":0,"nombreBeneficiario2":"","apellidoBeneficiario2":"","parentescoBeneficiario2":"","designacionBeneficiario2":0,"nombreBeneficiario3":"","apellidoBeneficiario3":"","parentescoBeneficiario3":"","designacionBeneficiario3":0,"beneficiariosRegistrados":false,"fechaRegistroBeneficiarios":""},"Emisión de Póliza":{"numeroCertificadoFinal":"","resultadoEmision":"","fechaVigenciaPoliza":"","polizaPrincipal":"","periodicidadPagoPoliza":"MENSUAL","confirmacionVentaSegurosBolivar":false,"liderClavo":"","certificado":"75272","observacionesEmision":"","fechaEmisionPoliza":"","estadoPoliza":"","numeroContrato":""}}
A9: 45881.787 | B9: 7847503 | C9: {"poliza":"11475","nombre":"DE JESUS FEREZ RAMIREZ","id":"18915352","telefono":"3165897782","correo":"wilsonferez@hotmail.com","ciudad":"FLORIDABLANCA","direccion":"CR 23 27 51","tipoInmueble":"Vivienda","canon":"1737000","fechaRadicacion":"12/8/2025","fechaAprobacion":"12/8/2025","estado":"APROBADA"} | D9: cristian.mosquera@segurosbolivar.com | E9: Contacto Inicial y Datos | F9: DESISTIDO | G9: Seguro de Vida | H9: [{"fecha":"2025-08-13 08:09:29","usuario":"olga.obando@segurosbolivar.com","accionRealizada":"Cliente no contesta","leadEtapaActual":"Contacto Inicial y Datos","productosGestion":"Seguro de Vida","observaciones":"2 INTENTOS SIN RESPUESTA"},{"fecha":"2025-08-13 09:42:46","usuario":"olga.obando@segurosbolivar.com","accionRealizada":"DESISTIDO","leadEtapaActual":"Contacto Inicial y Datos","productosGestion":"Seguro de Vida","observaciones":"No Contesta"}] | I9: 45882.405 | J9: {"Contacto Inicial y Datos":{"nomAgt":"","emailCte":"","autorizaDatosPersonales":false,"fechaNacimiento":"1999-01-01","tipoDocumento":"CC","observacionesPresentacion":"2 INTENTOS SIN RESPUESTA","genero":"Masculino","resultadoGestion":"Cliente ilocalizable","accion":"Cliente ilocalizable","usuario":"olga.obando@segurosbolivar.com"},"Cotización y Pre-Asegurabilidad":{"periosidad":"","nPagosMensuales":"","admin":"","observacionesCotizacion":"","valorAseguradoVida":0,"primaVidaITP":0,"fechaCotizacionVida":""},"Declaración de Asegurabilidad":{"actividadesLicita":false,"procesoPenal":false,"frecuenciaDeportesAltoRiesgo":"","peso":"","estatura":"","imcCalculado":"","observacionImc":"","estadoAsegurabilidad":"","hipertensionArterial":false,"colesterolTrigliceridosElevados":false,"diabetes":false,"enfermedadCoronariaInfarto":false,"insuficienciaRenal":false,"cancerTumores":false,"derrameTrombosisCerebral":false,"enfermedadesPsicologicasPsiquiatricas":false,"sidaVih":false,"pruebaVihPositiva":false,"secuelasEnfermedadAccidente":"","diagnosticoEnfermedadFracturas":"","tratamientoAlcoholAlucinogenos":false,"cirugiaProgramada":false,"autorizacionInformacionMedica":false,"fechaAsegurabilidad":""},"Autorización de Descuento Débito":{"canalDescuento":"","tipoDeCuenta":"","entidadBancaria":"","numeroCuentaDebito":"","fechaVencimientoTC":"","numeroCuotasTC":"","autorizaDescuentoAutomatico":false,"entiendeMoraPrima":false,"valorPrima":0,"fechaAutorizacionDebito":"","observacionesCierre":""},"Beneficiarios y Autorizaciones":{"nombreBeneficiario1":"","apellidoBeneficiario1":"","parentescoBeneficiario1":"","designacionBeneficiario1":0,"nombreBeneficiario2":"","apellidoBeneficiario2":"","parentescoBeneficiario2":"","designacionBeneficiario2":0,"nombreBeneficiario3":"","apellidoBeneficiario3":"","parentescoBeneficiario3":"","designacionBeneficiario3":0,"beneficiariosRegistrados":false,"fechaRegistroBeneficiarios":""},"Emisión de Póliza":{"numeroCertificadoFinal":"","resultadoEmision":"","fechaVigenciaPoliza":"","polizaPrincipal":"","periodicidadPagoPoliza":"MENSUAL","confirmacionVentaSegurosBolivar":false,"liderClavo":"","certificado":"75272","observacionesEmision":"","fechaEmisionPoliza":"","estadoPoliza":"","numeroContrato":""}}
A10: 45881.787 | B10: 7847796 | C10: {"poliza":"13187","nombre":"MARIA NATACHA AGUDELO BERMUDEZ","id":"1036607917","telefono":"3003630656","correo":"NATA1310@HOTMAIL.ES","ciudad":"ITAGUI","direccion":"CL 81A 52A 57 OF 201","tipoInmueble":"Comercial","canon":"2700000","fechaRadicacion":"11/8/2025","fechaAprobacion":"12/8/2025","estado":"APROBADA"} | D10: angela.caipa@segurosbolivar.com | E10: Contacto Inicial y Datos | F10: DESISTIDO | G10: Seguro de Vida | H10: [{"fecha":"2025-08-13 08:22:58","usuario":"angela.caipa@segurosbolivar.com","accionRealizada":"DESISTIDO","leadEtapaActual":"Contacto Inicial y Datos","productosGestion":"Seguro de Vida","observaciones":"Contesta y Cuelga Inmediatamente"}] | I10: 45882.349 | J10: {"Contacto Inicial y Datos":{"nomAgt":"","emailCte":"","autorizaDatosPersonales":false,"fechaNacimiento":"","tipoDocumento":"CC","observacionesPresentacion":"cuelga al preguntar por ella","genero":"Femenino","resultadoGestion":"Cliente ilocalizable","accion":"Cliente ilocalizable","usuario":"angela.caipa@segurosbolivar.com"},"Cotización y Pre-Asegurabilidad":{"periosidad":"","nPagosMensuales":"","admin":"","observacionesCotizacion":"","valorAseguradoVida":0,"primaVidaITP":0,"fechaCotizacionVida":""},"Declaración de Asegurabilidad":{"actividadesLicita":false,"procesoPenal":false,"frecuenciaDeportesAltoRiesgo":"","peso":"","estatura":"","imcCalculado":"","observacionImc":"","estadoAsegurabilidad":"","hipertensionArterial":false,"colesterolTrigliceridosElevados":false,"diabetes":false,"enfermedadCoronariaInfarto":false,"insuficienciaRenal":false,"cancerTumores":false,"derrameTrombosisCerebral":false,"enfermedadesPsicologicasPsiquiatricas":false,"sidaVih":false,"pruebaVihPositiva":false,"secuelasEnfermedadAccidente":"","diagnosticoEnfermedadFracturas":"","tratamientoAlcoholAlucinogenos":false,"cirugiaProgramada":false,"autorizacionInformacionMedica":false,"fechaAsegurabilidad":""},"Autorización de Descuento Débito":{"canalDescuento":"","tipoDeCuenta":"","entidadBancaria":"","numeroCuentaDebito":"","fechaVencimientoTC":"","numeroCuotasTC":"","autorizaDescuentoAutomatico":false,"entiendeMoraPrima":false,"valorPrima":0,"fechaAutorizacionDebito":"","observacionesCierre":""},"Beneficiarios y Autorizaciones":{"nombreBeneficiario1":"","apellidoBeneficiario1":"","parentescoBeneficiario1":"","designacionBeneficiario1":0,"nombreBeneficiario2":"","apellidoBeneficiario2":"","parentescoBeneficiario2":"","designacionBeneficiario2":0,"nombreBeneficiario3":"","apellidoBeneficiario3":"","parentescoBeneficiario3":"","designacionBeneficiario3":0,"beneficiariosRegistrados":false,"fechaRegistroBeneficiarios":""},"Emisión de Póliza":{"numeroCertificadoFinal":"","resultadoEmision":"","fechaVigenciaPoliza":"","polizaPrincipal":"","periodicidadPagoPoliza":"MENSUAL","confirmacionVentaSegurosBolivar":false,"liderClavo":"","certificado":"75272","observacionesEmision":"","fechaEmisionPoliza":"","estadoPoliza":"","numeroContrato":""}}
A11: 45881.787 | B11: 7847839 | C11: {"poliza":"10913","nombre":"ELVIS SIPRIAN CASTRO ALZATE","id":"14838008","telefono":"3166280479","correo":"ELVIS.CASTRO@CORREOUNIVALLE.EDU.CO","ciudad":"CALI","direccion":"CR 48 4 71 AP 306 TORRE D UR ANTONIO NARI O","tipoInmueble":"Vivienda","canon":"876000","fechaRadicacion":"12/8/2025","fechaAprobacion":"12/8/2025","estado":"APROBADA"} | D11: cristian.mosquera@segurosbolivar.com | E11: Contacto Inicial y Datos | F11: DESISTIDO | G11: Seguro de Vida | H11: [{"fecha":"2025-08-13 08:12:09","usuario":"mildre.rico@segurosbolivar.com","accionRealizada":"DESISTIDO","leadEtapaActual":"Contacto Inicial y Datos","productosGestion":"Seguro de Vida","observaciones":"Cambio de inmueble"}] | I11: 45882.342 | J11: {"Contacto Inicial y Datos":{"nomAgt":"","emailCte":"","autorizaDatosPersonales":false,"fechaNacimiento":"","tipoDocumento":"","observacionesPresentacion":"NO TOMRAA EL INMUEBLE","genero":"Masculino","resultadoGestion":"Venta Cancelada","accion":"Venta Cancelada","usuario":"mildre.rico@segurosbolivar.com"},"Cotización y Pre-Asegurabilidad":{"periosidad":"","nPagosMensuales":"","admin":"","observacionesCotizacion":"","valorAseguradoVida":0,"primaVidaITP":0,"fechaCotizacionVida":""},"Declaración de Asegurabilidad":{"actividadesLicita":false,"procesoPenal":false,"frecuenciaDeportesAltoRiesgo":"","peso":"","estatura":"","imcCalculado":"","observacionImc":"","estadoAsegurabilidad":"","hipertensionArterial":false,"colesterolTrigliceridosElevados":false,"diabetes":false,"enfermedadCoronariaInfarto":false,"insuficienciaRenal":false,"cancerTumores":false,"derrameTrombosisCerebral":false,"enfermedadesPsicologicasPsiquiatricas":false,"sidaVih":false,"pruebaVihPositiva":false,"secuelasEnfermedadAccidente":"","diagnosticoEnfermedadFracturas":"","tratamientoAlcoholAlucinogenos":false,"cirugiaProgramada":false,"autorizacionInformacionMedica":false,"fechaAsegurabilidad":""},"Autorización de Descuento Débito":{"canalDescuento":"","tipoDeCuenta":"","entidadBancaria":"","numeroCuentaDebito":"","fechaVencimientoTC":"","numeroCuotasTC":"","autorizaDescuentoAutomatico":false,"entiendeMoraPrima":false,"valorPrima":0,"fechaAutorizacionDebito":"","observacionesCierre":""},"Beneficiarios y Autorizaciones":{"nombreBeneficiario1":"","apellidoBeneficiario1":"","parentescoBeneficiario1":"","designacionBeneficiario1":0,"nombreBeneficiario2":"","apellidoBeneficiario2":"","parentescoBeneficiario2":"","designacionBeneficiario2":0,"nombreBeneficiario3":"","apellidoBeneficiario3":"","parentescoBeneficiario3":"","designacionBeneficiario3":0,"beneficiariosRegistrados":false,"fechaRegistroBeneficiarios":""},"Emisión de Póliza":{"numeroCertificadoFinal":"","resultadoEmision":"","fechaVigenciaPoliza":"","polizaPrincipal":"","periodicidadPagoPoliza":"MENSUAL","confirmacionVentaSegurosBolivar":false,"liderClavo":"","certificado":"75272","observacionesEmision":"","fechaEmisionPoliza":"","estadoPoliza":"","numeroContrato":""}}
A12: 45881.787 | B12: 11695035 | C12: {"poliza":"13573","nombre":"MONICA MARIA PUERTA GALLO","id":"1017150295","telefono":"3022650431","correo":"puertamonicamaria@gmail.com","ciudad":"COPACABANA","direccion":"PENDIENTE","tipoInmueble":"Vivienda","canon":"900000","fechaRadicacion":"9/8/2025","fechaAprobacion":"12/8/2025","estado":"APROBADA"} | D12: Anyuley.daza@aselibertador.com | E12: Contacto Inicial y Datos | F12: DESISTIDO | G12: Seguro de Vida | H12: [{"fecha":"2025-08-13 08:14:41","usuario":"anyuley.daza@aselibertador.com","accionRealizada":"DESISTIDO","leadEtapaActual":"Contacto Inicial y Datos","productosGestion":"Seguro de Vida","observaciones":"No Contesta"}] | I12: 45882.344 | J12: {"Contacto Inicial y Datos":{"nomAgt":"","emailCte":"","autorizaDatosPersonales":false,"fechaNacimiento":"","tipoDocumento":"CC","observacionesPresentacion":"","genero":"Femenino","resultadoGestion":"Cliente ilocalizable","accion":"Cliente ilocalizable","usuario":"anyuley.daza@aselibertador.com"},"Cotización y Pre-Asegurabilidad":{"periosidad":"","nPagosMensuales":"","admin":"","observacionesCotizacion":"","valorAseguradoVida":0,"primaVidaITP":0,"fechaCotizacionVida":""},"Declaración de Asegurabilidad":{"actividadesLicita":false,"procesoPenal":false,"frecuenciaDeportesAltoRiesgo":"","peso":"","estatura":"","imcCalculado":"","observacionImc":"","estadoAsegurabilidad":"","hipertensionArterial":false,"colesterolTrigliceridosElevados":false,"diabetes":false,"enfermedadCoronariaInfarto":false,"insuficienciaRenal":false,"cancerTumores":false,"derrameTrombosisCerebral":false,"enfermedadesPsicologicasPsiquiatricas":false,"sidaVih":false,"pruebaVihPositiva":false,"secuelasEnfermedadAccidente":"","diagnosticoEnfermedadFracturas":"","tratamientoAlcoholAlucinogenos":false,"cirugiaProgramada":false,"autorizacionInformacionMedica":false,"fechaAsegurabilidad":""},"Autorización de Descuento Débito":{"canalDescuento":"","tipoDeCuenta":"","entidadBancaria":"","numeroCuentaDebito":"","fechaVencimientoTC":"","numeroCuotasTC":"","autorizaDescuentoAutomatico":false,"entiendeMoraPrima":false,"valorPrima":0,"fechaAutorizacionDebito":"","observacionesCierre":""},"Beneficiarios y Autorizaciones":{"nombreBeneficiario1":"","apellidoBeneficiario1":"","parentescoBeneficiario1":"","designacionBeneficiario1":0,"nombreBeneficiario2":"","apellidoBeneficiario2":"","parentescoBeneficiario2":"","designacionBeneficiario2":0,"nombreBeneficiario3":"","apellidoBeneficiario3":"","parentescoBeneficiario3":"","designacionBeneficiario3":0,"beneficiariosRegistrados":false,"fechaRegistroBeneficiarios":""},"Emisión de Póliza":{"numeroCertificadoFinal":"","resultadoEmision":"","fechaVigenciaPoliza":"","polizaPrincipal":"","periodicidadPagoPoliza":"MENSUAL","confirmacionVentaSegurosBolivar":false,"liderClavo":"","certificado":"75272","observacionesEmision":"","fechaEmisionPoliza":"","estadoPoliza":"","numeroContrato":""}}
A13: 45881.787 | B13: 11695057 | C13: {"poliza":"13404","nombre":"EDWIN MAURICIO PEÑA RUBIO","id":"1121830090","telefono":"3216051933","correo":"rubio_090@hotmail.com","ciudad":"MEDELLIN","direccion":"CL 58 #31 36 P 1","tipoInmueble":"Vivienda","canon":"1150000","fechaRadicacion":"9/8/2025","fechaAprobacion":"12/8/2025","estado":"APROBADA"} | D13: ana.prieto@aselibertador.com | E13: Contacto Inicial y Datos | F13: DESISTIDO | G13: Seguro de Vida | H13: [{"fecha":"2025-08-13 09:16:31","usuario":"ana.prieto@aselibertador.com","accionRealizada":"DESISTIDO","leadEtapaActual":"Contacto Inicial y Datos","productosGestion":"Seguro de Vida","observaciones":"No Contesta"}] | I13: 45882.386 | J13: {"Contacto Inicial y Datos":{"nomAgt":"","emailCte":"","autorizaDatosPersonales":false,"fechaNacimiento":"","tipoDocumento":"","observacionesPresentacion":"","genero":"","resultadoGestion":"Cliente ilocalizable","accion":"Cliente ilocalizable","usuario":"ana.prieto@aselibertador.com"},"Cotización y Pre-Asegurabilidad":{"periosidad":"","nPagosMensuales":"","admin":"","observacionesCotizacion":"","valorAseguradoVida":0,"primaVidaITP":0,"fechaCotizacionVida":""},"Declaración de Asegurabilidad":{"actividadesLicita":false,"procesoPenal":false,"frecuenciaDeportesAltoRiesgo":"","peso":"","estatura":"","imcCalculado":"","observacionImc":"","estadoAsegurabilidad":"","hipertensionArterial":false,"colesterolTrigliceridosElevados":false,"diabetes":false,"enfermedadCoronariaInfarto":false,"insuficienciaRenal":false,"cancerTumores":false,"derrameTrombosisCerebral":false,"enfermedadesPsicologicasPsiquiatricas":false,"sidaVih":false,"pruebaVihPositiva":false,"secuelasEnfermedadAccidente":"","diagnosticoEnfermedadFracturas":"","tratamientoAlcoholAlucinogenos":false,"cirugiaProgramada":false,"autorizacionInformacionMedica":false,"fechaAsegurabilidad":""},"Autorización de Descuento Débito":{"canalDescuento":"","tipoDeCuenta":"","entidadBancaria":"","numeroCuentaDebito":"","fechaVencimientoTC":"","numeroCuotasTC":"","autorizaDescuentoAutomatico":false,"entiendeMoraPrima":false,"valorPrima":0,"fechaAutorizacionDebito":"","observacionesCierre":""},"Beneficiarios y Autorizaciones":{"nombreBeneficiario1":"","apellidoBeneficiario1":"","parentescoBeneficiario1":"","designacionBeneficiario1":0,"nombreBeneficiario2":"","apellidoBeneficiario2":"","parentescoBeneficiario2":"","designacionBeneficiario2":0,"nombreBeneficiario3":"","apellidoBeneficiario3":"","parentescoBeneficiario3":"","designacionBeneficiario3":0,"beneficiariosRegistrados":false,"fechaRegistroBeneficiarios":""},"Emisión de Póliza":{"numeroCertificadoFinal":"","resultadoEmision":"","fechaVigenciaPoliza":"","polizaPrincipal":"","periodicidadPagoPoliza":"MENSUAL","confirmacionVentaSegurosBolivar":false,"liderClavo":"","certificado":"75272","observacionesEmision":"","fechaEmisionPoliza":"","estadoPoliza":"","numeroContrato":""}}
A14: 45881.787 | B14: 11695063 | C14: {"poliza":"1993","nombre":"JUAN DAVID BAYONA RAMIREZ","id":"1020757640","telefono":"3168789731","correo":"eyobayona@hotmail.com","ciudad":"BOGOTA, D.C.","direccion":"CR 19A 104 48","tipoInmueble":"Vivienda","canon":"2515616","fechaRadicacion":"9/8/2025","fechaAprobacion":"12/8/2025","estado":"APROBADA"} | D14: diana.salas@segurosbolivar.com | E14: Contacto Inicial y Datos | F14: DESISTIDO | G14: Seguro de Vida | H14: [{"fecha":"2025-08-13 08:27:08","usuario":"diana.salas@segurosbolivar.com","accionRealizada":"DESISTIDO","leadEtapaActual":"Contacto Inicial y Datos","productosGestion":"Seguro de Vida","observaciones":"No le interesa"}] | I14: 45882.352 | J14: {"Contacto Inicial y Datos":{"nomAgt":"","emailCte":"","autorizaDatosPersonales":false,"fechaNacimiento":"","tipoDocumento":"CC","observacionesPresentacion":"","genero":"","resultadoGestion":"Cliente no interesado","accion":"Cliente no interesado","usuario":"diana.salas@segurosbolivar.com"},"Cotización y Pre-Asegurabilidad":{"periosidad":"","nPagosMensuales":"","admin":"","observacionesCotizacion":"","valorAseguradoVida":0,"primaVidaITP":0,"fechaCotizacionVida":""},"Declaración de Asegurabilidad":{"actividadesLicita":false,"procesoPenal":false,"frecuenciaDeportesAltoRiesgo":"","peso":"","estatura":"","imcCalculado":"","observacionImc":"","estadoAsegurabilidad":"","hipertensionArterial":false,"colesterolTrigliceridosElevados":false,"diabetes":false,"enfermedadCoronariaInfarto":false,"insuficienciaRenal":false,"cancerTumores":false,"derrameTrombosisCerebral":false,"enfermedadesPsicologicasPsiquiatricas":false,"sidaVih":false,"pruebaVihPositiva":false,"secuelasEnfermedadAccidente":"","diagnosticoEnfermedadFracturas":"","tratamientoAlcoholAlucinogenos":false,"cirugiaProgramada":false,"autorizacionInformacionMedica":false,"fechaAsegurabilidad":""},"Autorización de Descuento Débito":{"canalDescuento":"","tipoDeCuenta":"","entidadBancaria":"","numeroCuentaDebito":"","fechaVencimientoTC":"","numeroCuotasTC":"","autorizaDescuentoAutomatico":false,"entiendeMoraPrima":false,"valorPrima":0,"fechaAutorizacionDebito":"","observacionesCierre":""},"Beneficiarios y Autorizaciones":{"nombreBeneficiario1":"","apellidoBeneficiario1":"","parentescoBeneficiario1":"","designacionBeneficiario1":0,"nombreBeneficiario2":"","apellidoBeneficiario2":"","parentescoBeneficiario2":"","designacionBeneficiario2":0,"nombreBeneficiario3":"","apellidoBeneficiario3":"","parentescoBeneficiario3":"","designacionBeneficiario3":0,"beneficiariosRegistrados":false,"fechaRegistroBeneficiarios":""},"Emisión de Póliza":{"numeroCertificadoFinal":"","resultadoEmision":"","fechaVigenciaPoliza":"","polizaPrincipal":"","periodicidadPagoPoliza":"MENSUAL","confirmacionVentaSegurosBolivar":false,"liderClavo":"","certificado":"75272","observacionesEmision":"","fechaEmisionPoliza":"","estadoPoliza":"","numeroContrato":""}}
A15: 45881.787 | B15: 11695100 | C15: {"poliza":"10017","nombre":"ANGELA MARIA LOPEZ VALENCIA","id":"31575495","telefono":"3164688197","correo":"amalova17@hotmail.com","ciudad":"CALI","direccion":"CL 13E 65 C 55","tipoInmueble":"Vivienda","canon":"2300000","fechaRadicacion":"9/8/2025","fechaAprobacion":"12/8/2025","estado":"APROBADA"} | D15: maria.gaitan@proyectivaseguros.com | E15: Contacto Inicial y Datos | F15: DESISTIDO | G15: Seguro de Vida | H15: [{"fecha":"2025-08-13 08:18:30","usuario":"maria.gaitan@segurosbolivar.com","accionRealizada":"DESISTIDO","leadEtapaActual":"Contacto Inicial y Datos","productosGestion":"Seguro de Vida","observaciones":"No Contesta"}] | I15: 45882.346 | J15: {"Contacto Inicial y Datos":{"nomAgt":"","emailCte":"","autorizaDatosPersonales":false,"fechaNacimiento":"","tipoDocumento":"CC","observacionesPresentacion":"","genero":"Femenino","resultadoGestion":"Cliente ilocalizable","accion":"Cliente ilocalizable","usuario":"maria.gaitan@segurosbolivar.com"},"Cotización y Pre-Asegurabilidad":{"periosidad":"Mensual","nPagosMensuales":"12","admin":"","observacionesCotizacion":"","valorAseguradoVida":0,"primaVidaITP":0,"fechaCotizacionVida":"","resultadoGestion":""},"Declaración de Asegurabilidad":{"actividadesLicita":false,"procesoPenal":false,"frecuenciaDeportesAltoRiesgo":"","peso":"","estatura":"","imcCalculado":"","observacionImc":"","estadoAsegurabilidad":"","hipertensionArterial":false,"colesterolTrigliceridosElevados":false,"diabetes":false,"enfermedadCoronariaInfarto":false,"insuficienciaRenal":false,"cancerTumores":false,"derrameTrombosisCerebral":false,"enfermedadesPsicologicasPsiquiatricas":false,"sidaVih":false,"pruebaVihPositiva":false,"secuelasEnfermedadAccidente":"","diagnosticoEnfermedadFracturas":"","tratamientoAlcoholAlucinogenos":false,"cirugiaProgramada":false,"autorizacionInformacionMedica":false,"fechaAsegurabilidad":""},"Autorización de Descuento Débito":{"canalDescuento":"","tipoDeCuenta":"","entidadBancaria":"","numeroCuentaDebito":"","fechaVencimientoTC":"","numeroCuotasTC":"","autorizaDescuentoAutomatico":false,"entiendeMoraPrima":false,"valorPrima":0,"fechaAutorizacionDebito":"","observacionesCierre":""},"Beneficiarios y Autorizaciones":{"nombreBeneficiario1":"","apellidoBeneficiario1":"","parentescoBeneficiario1":"","designacionBeneficiario1":0,"nombreBeneficiario2":"","apellidoBeneficiario2":"","parentescoBeneficiario2":"","designacionBeneficiario2":0,"nombreBeneficiario3":"","apellidoBeneficiario3":"","parentescoBeneficiario3":"","designacionBeneficiario3":0,"beneficiariosRegistrados":false,"fechaRegistroBeneficiarios":""},"Emisión de Póliza":{"numeroCertificadoFinal":"","resultadoEmision":"","fechaVigenciaPoliza":"","polizaPrincipal":"","periodicidadPagoPoliza":"MENSUAL","confirmacionVentaSegurosBolivar":false,"liderClavo":"","certificado":"75272","observacionesEmision":"","fechaEmisionPoliza":"","estadoPoliza":"","numeroContrato":""}}
A16: 45881.787 | B16: 11695127 | C16: {"poliza":"13404","nombre":"JHOEL ESTEBAN SÁNCHEZ MONSALVE","id":"1032259700","telefono":"3006664693","correo":"maryuli1957@gmail.com","ciudad":"MEDELLIN","direccion":"CRA 79 A #111 29","tipoInmueble":"Vivienda","canon":"900000","fechaRadicacion":"9/8/2025","fechaAprobacion":"12/8/2025","estado":"APROBADA"} | D16: olga.obando@proyectivaseguros.com | E16: Declaración de Asegurabilidad | F16: DESISTIDO | G16: Seguro de Vida | H16: [{"fecha":"2025-08-13 08:21:20","usuario":"olga.obando@segurosbolivar.com","accionRealizada":"DESISTIDO","leadEtapaActual":"Declaración de Asegurabilidad","productosGestion":"Seguro de Vida","observaciones":"Declaración"},{"fecha":"2025-08-13 08:22:54","usuario":"olga.obando@segurosbolivar.com","accionRealizada":"DESISTIDO","leadEtapaActual":"Declaración de Asegurabilidad","productosGestion":"Seguro de Vida","observaciones":"Declaración"}] | I16: 45882.349 | J16: {"Contacto Inicial y Datos":{"nomAgt":"olga.obando@segurosbolivar.com","emailCte":"","autorizaDatosPersonales":true,"fechaNacimiento":"1996-05-15","tipoDocumento":"CC","observacionesPresentacion":"TODO OK","genero":"Masculino","resultadoGestion":"Cliente acepta tratamiento de datos personales","accion":"Cliente acepta tratamiento de datos personales","usuario":"olga.obando@segurosbolivar.com"},"Cotización y Pre-Asegurabilidad":{"periosidad":"Mensual","nPagosMensuales":"24","admin":"","observacionesCotizacion":"TODO","valorAseguradoVida":21600000,"primaVidaITP":22140.000000000004,"fechaCotizacionVida":"13/8/2025","resultadoGestion":"Cliente acepta Cotización","accion":"Cliente acepta Cotización","usuario":"olga.obando@segurosbolivar.com"},"Declaración de Asegurabilidad":{"actividadesLicita":true,"procesoPenal":true,"frecuenciaDeportesAltoRiesgo":"0","peso":"","estatura":"","imcCalculado":"","observacionImc":"","estadoAsegurabilidad":"","hipertensionArterial":false,"colesterolTrigliceridosElevados":false,"diabetes":false,"enfermedadCoronariaInfarto":false,"insuficienciaRenal":false,"cancerTumores":false,"derrameTrombosisCerebral":false,"enfermedadesPsicologicasPsiquiatricas":false,"sidaVih":false,"pruebaVihPositiva":false,"secuelasEnfermedadAccidente":"","diagnosticoEnfermedadFracturas":"","tratamientoAlcoholAlucinogenos":false,"cirugiaProgramada":false,"autorizacionInformacionMedica":false,"fechaAsegurabilidad":"","sarlaft":false,"resultadoGestion":"No Asegurable","observacionesNegociacion":"IMC ELEVADO 33,30","accion":"No Asegurable","usuario":"olga.obando@segurosbolivar.com"},"Autorización de Descuento Débito":{"canalDescuento":"","tipoDeCuenta":"","entidadBancaria":"","numeroCuentaDebito":"","fechaVencimientoTC":"","numeroCuotasTC":"","autorizaDescuentoAutomatico":false,"entiendeMoraPrima":false,"valorPrima":0,"fechaAutorizacionDebito":"","observacionesCierre":""},"Beneficiarios y Autorizaciones":{"nombreBeneficiario1":"","apellidoBeneficiario1":"","parentescoBeneficiario1":"","designacionBeneficiario1":0,"nombreBeneficiario2":"","apellidoBeneficiario2":"","parentescoBeneficiario2":"","designacionBeneficiario2":0,"nombreBeneficiario3":"","apellidoBeneficiario3":"","parentescoBeneficiario3":"","designacionBeneficiario3":0,"beneficiariosRegistrados":false,"fechaRegistroBeneficiarios":""},"Emisión de Póliza":{"numeroCertificadoFinal":"","resultadoEmision":"","fechaVigenciaPoliza":"","polizaPrincipal":"","periodicidadPagoPoliza":"MENSUAL","confirmacionVentaSegurosBolivar":false,"liderClavo":"","certificado":"75272","observacionesEmision":"","fechaEmisionPoliza":"","estadoPoliza":"","numeroContrato":""}}
A17: 45881.787 | B17: 11695130 | C17: {"poliza":"13818","nombre":"LUIS ALBERTO MERCADO AGUAS","id":"1103109777","telefono":"3013751548","correo":"marmag992@gmail.com","ciudad":"MEDELLIN","direccion":"CR 93 # 82 59 AURES II","tipoInmueble":"Vivienda","canon":"950000","fechaRadicacion":"9/8/2025","fechaAprobacion":"12/8/2025","estado":"APROBADA"} | D17: angela.caipa@segurosbolivar.com | E17: Contacto Inicial y Datos | F17: DESISTIDO | G17: Seguro de Vida | H17: [{"fecha":"2025-08-13 08:31:57","usuario":"angela.caipa@segurosbolivar.com","accionRealizada":"Cliente no contesta","leadEtapaActual":"Contacto Inicial y Datos","productosGestion":"Seguro de Vida","observaciones":"Sin observaciones específicas"},{"fecha":"2025-08-13 09:28:00","usuario":"angela.caipa@segurosbolivar.com","accionRealizada":"DESISTIDO","leadEtapaActual":"Contacto Inicial y Datos","productosGestion":"Seguro de Vida","observaciones":"No Contesta"}] | I17: 45882.394 | J17: {"Contacto Inicial y Datos":{"nomAgt":"","emailCte":"","autorizaDatosPersonales":false,"fechaNacimiento":"2025-08-13","tipoDocumento":"","observacionesPresentacion":"","genero":"","resultadoGestion":"Cliente ilocalizable","accion":"Cliente ilocalizable","usuario":"angela.caipa@segurosbolivar.com"},"Cotización y Pre-Asegurabilidad":{"periosidad":"","nPagosMensuales":"","admin":"","observacionesCotizacion":"","valorAseguradoVida":0,"primaVidaITP":0,"fechaCotizacionVida":""},"Declaración de Asegurabilidad":{"actividadesLicita":false,"procesoPenal":false,"frecuenciaDeportesAltoRiesgo":"","peso":"","estatura":"","imcCalculado":"","observacionImc":"","estadoAsegurabilidad":"","hipertensionArterial":false,"colesterolTrigliceridosElevados":false,"diabetes":false,"enfermedadCoronariaInfarto":false,"insuficienciaRenal":false,"cancerTumores":false,"derrameTrombosisCerebral":false,"enfermedadesPsicologicasPsiquiatricas":false,"sidaVih":false,"pruebaVihPositiva":false,"secuelasEnfermedadAccidente":"","diagnosticoEnfermedadFracturas":"","tratamientoAlcoholAlucinogenos":false,"cirugiaProgramada":false,"autorizacionInformacionMedica":false,"fechaAsegurabilidad":""},"Autorización de Descuento Débito":{"canalDescuento":"","tipoDeCuenta":"","entidadBancaria":"","numeroCuentaDebito":"","fechaVencimientoTC":"","numeroCuotasTC":"","autorizaDescuentoAutomatico":false,"entiendeMoraPrima":false,"valorPrima":0,"fechaAutorizacionDebito":"","observacionesCierre":""},"Beneficiarios y Autorizaciones":{"nombreBeneficiario1":"","apellidoBeneficiario1":"","parentescoBeneficiario1":"","designacionBeneficiario1":0,"nombreBeneficiario2":"","apellidoBeneficiario2":"","parentescoBeneficiario2":"","designacionBeneficiario2":0,"nombreBeneficiario3":"","apellidoBeneficiario3":"","parentescoBeneficiario3":"","designacionBeneficiario3":0,"beneficiariosRegistrados":false,"fechaRegistroBeneficiarios":""},"Emisión de Póliza":{"numeroCertificadoFinal":"","resultadoEmision":"","fechaVigenciaPoliza":"","polizaPrincipal":"","periodicidadPagoPoliza":"MENSUAL","confirmacionVentaSegurosBolivar":false,"liderClavo":"","certificado":"75272","observacionesEmision":"","fechaEmisionPoliza":"","estadoPoliza":"","numeroContrato":""}}
